Workbook
Name IQ_CH: 110000
Name IQ_CQ: 5000
Name IQ_CY: 10000
Name IQ_DAILY: 500000
Name IQ_FH: 100000
Name IQ_FQ: 500
Name IQ_FY: 1000
Name IQ_LTM: 2000
Name IQ_MONTH: 15000
Name IQ_NTM: 6000
Name IQ_WEEK: 50000
Name IQ_YTD: 3000

Sheet Financials
B2: Company name
B3: All amounts in Millions except per share data (inputs in blue)
B5: =$B$2& " Valuation Summary" -> Company name Valuation Summary
B7: Fiscal Year | D7: 2016 | E7: =D7+1 -> 2017 | F7: =E7+1 -> 2018 | G7: =F7+1 -> 2019 | H7: =G7+1 -> 2020 | I7: =H7+1 -> 2021 | J7: =I7+1 -> 2022 | K7: =J7+1 -> 2023 | L7: =K7+1 -> 2024 | M7: =L7+1 -> 2025
B8: Company symbol
B9: Share price date
B10: Share Price:
B11: Shares Outstanding
B12: Market Cap | D12: =+D10*D11 -> 0 | E12: =+E10*E11 -> 0 | F12: =+F10*F11 -> 0 | G12: =+G10*G11 -> 0 | H12: =+H11*H10 -> 0 | I12: =+I11*I10 -> 0 | J12: =+J11*J10 -> 0 | K12: =+K11*K10 -> 0 | L12: =+L11*L10 -> 0 | M12: =+M11*M10 -> 0
B13: Less: Cash + securities | D13: =D53+D59 | E13: =E53+E59 | F13: =F53+F59 | G13: =G53+G59 | H13: =H53+H59 | I13: =I53+I59 | J13: =J53+J59 | K13: =K53+K59 | ... M13: =M53+M59
B14: Plus: Debt | D14: =D64 -> 0 | E14: =E64 -> 0 | F14: =F64 -> 0 | G14: =G64 -> 0 | H14: =H64 -> 0 | I14: =I64 -> 0 | J14: =J64 -> 0 | K14: =K64 -> 0 | ... M14: =M64 -> 0
B15: Enterprise Value | D15: =D12-D13+D14 -> 0 | E15: =E12-E13+E14 -> 0 | F15: =F12-F13+F14 -> 0 | G15: =G12-G13+G14 -> 0 | H15: =H12-H13+H14 -> 0 | I15: =I12-I13+I14 -> 0 | J15: =J12-J13+J14 -> 0 | K15: =K12-K13+K14 -> 0 | ... M15: =M12-M13+M14 -> 0
B16: EV/share | D16: =+D15/D11 -> #DIV/0! | E16: =+E15/E11 -> #DIV/0! | F16: =+F15/F11 -> #DIV/0! | G16: =+G15/G11 -> #DIV/0! | H16: =+H15/H11 -> #DIV/0! | I16: =+I15/I11 -> #DIV/0! | J16: =+J15/J11 -> #DIV/0! | K16: =+K15/K11 -> #DIV/0! | ... M16: =+M15/M11 -> #DIV/0!
B17: Book Value (Equity) | D17: =D68 -> 0 | E17: =E68 -> 0 | F17: =F68 -> 0 | G17: =G68 -> 0 | H17: =H68 -> 0 | I17: =I68 -> 0 | J17: =J68 -> 0 | K17: =K68 -> 0 | ... M17: =M68 -> 0
B20: ="Summary Values - " & M7 & " (per share basis)" -> Summary Values - 2025 (per share basis)
B21: Invested Capital | D21: =M138/M11 -> #DIV/0! | E21: =+D21/$D$25 -> #DIV/0!
B22: PV of Comp Advantage | D22: =M139/M11 -> #DIV/0! | E22: =+D22/$D$25 -> #DIV/0!
B23: Earnings Power Value | D23: =M140/M11 -> #DIV/0! | E23: =+D23/$D$25 -> #DIV/0!
B24: Market implied value of growth | D24: =M142/M11 -> #DIV/0! | E24: =+D24/$D$25 -> #DIV/0!
B25: EV/Share | D25: =+D23+D24 -> #DIV/0!
B28: =$B$2& " Historical Financials" -> Company name Historical Financials
B29: Income Statement
D30: =D7 -> 2016 | E30: =D30+1 -> 2017 | F30: =E30+1 -> 2018 | G30: =F30+1 -> 2019 | H30: =G30+1 -> 2020 | I30: =H30+1 -> 2021 | J30: =I30+1 -> 2022 | K30: =+K7 -> 2023 | L30: =+L7 -> 2024 | M30: =+M7 -> 2025
B31: Revenue
B32: COGS
B33: Gross Profit | D33: =SUM(D31:D32) -> 0 | E33: =SUM(E31:E32) -> 0 | F33: =SUM(F31:F32) -> 0 | G33: =SUM(G31:G32) -> 0 | H33: =SUM(H31:H32) -> 0 | I33: =SUM(I31:I32) -> 0 | J33: =SUM(J31:J32) -> 0 | K33: =SUM(K31:K32) -> 0 | ... M33: =SUM(M31:M32) -> 0
C34: GPM | D34: =D33/D31 -> #DIV/0! | E34: =E33/E31 -> #DIV/0! | F34: =F33/F31 -> #DIV/0! | G34: =G33/G31 -> #DIV/0! | H34: =H33/H31 -> #DIV/0! | I34: =I33/I31 -> #DIV/0! | J34: =J33/J31 -> #DIV/0! | K34: =K33/K31 -> #DIV/0! | ... M34: =M33/M31 -> #DIV/0!
B36: Operating Expenses (SG&A)
B38: Operating Profit | D38: =+D33-(D36+D37) -> 0 | E38: =+E33-(E36+E37) -> 0 | F38: =+F33-(F36+F37) -> 0 | G38: =+G33-(G36+G37) -> 0 | H38: =+H33-(H36+H37) -> 0 | I38: =+I33-(I36+I37) -> 0 | J38: =+J33-(J36+J37) -> 0 | K38: =+K33-(K36+K37) -> 0 | ... M38: =+M33-(M36+M37) -> 0
C39: OPM | D39: =D38/D31 -> #DIV/0! | E39: =E38/E31 -> #DIV/0! | F39: =F38/F31 -> #DIV/0! | G39: =G38/G31 -> #DIV/0! | H39: =H38/H31 -> #DIV/0! | I39: =I38/I31 -> #DIV/0! | J39: =J38/J31 -> #DIV/0! | K39: =K38/K31 -> #DIV/0! | ... M39: =M38/M31 -> #DIV/0!
B41: Interest and other income
B42: Income Before Taxes | D42: =+D38+D41 -> 0 | E42: =+E38+E41 -> 0 | F42: =+F38+F41 -> 0 | G42: =+G38+G41 -> 0 | H42: =+H38+H41 -> 0 | I42: =+I38+I41 -> 0 | J42: =+J38+J41 -> 0 | K42: =+K38+K41 -> 0 | ... M42: =+M38+M41 -> 0
B44: Taxes
C45: Rate | D45: =D44/D42 -> #DIV/0! | E45: =E44/E42 -> #DIV/0! | F45: =F44/F42 -> #DIV/0! | G45: =G44/G42 -> #DIV/0! | H45: =H44/H42 -> #DIV/0! | I45: =I44/I42 -> #DIV/0! | J45: =J44/J42 -> #DIV/0! | K45: =K44/K42 -> #DIV/0! | ... M45: =M44/M42 -> #DIV/0!
B46: Minority Interest in Earnings
B48: Net Income | D48: =+D42-D44+D46 -> 0 | E48: =+E42-E44+E46 -> 0 | F48: =+F42-F44+F46 -> 0 | G48: =+G42-G44+G46 -> 0 | H48: =+H42-H44+H46 -> 0 | I48: =+I42-I44+I46 -> 0 | J48: =+J42-J44+J46 -> 0 | K48: =+K42-K44+K46 -> 0 | ... M48: =+M42-M44+M46 -> 0
C49: Margin | D49: =D48/D31 -> #DIV/0! | E49: =E48/E31 -> #DIV/0! | F49: =F48/F31 -> #DIV/0! | G49: =G48/G31 -> #DIV/0! | H49: =H48/H31 -> #DIV/0! | I49: =I48/I31 -> #DIV/0! | J49: =J48/J31 -> #DIV/0! | K49: =K48/K31 -> #DIV/0! | ... M49: =M48/M31 -> #DIV/0!
B51: Balance Sheet
D52: =D7 -> 2016 | E52: =D52+1 -> 2017 | F52: =E52+1 -> 2018 | G52: =F52+1 -> 2019 | H52: =G52+1 -> 2020 | I52: =H52+1 -> 2021 | J52: =I52+1 -> 2022 | K52: =+K7 -> 2023 | L52: =+L7 -> 2024 | M52: =+M7 -> 2025
B53: Cash, Equivalents + Current Securities
...

Sheet Charts
C2: =Financials!D7 -> 2016 | D2: =Financials!E7 -> 2017 | E2: =Financials!F7 -> 2018 | F2: =Financials!G7 -> 2019 | G2: =Financials!H7 -> 2020 | H2: =Financials!I7 -> 2021 | I2: =Financials!J7 -> 2022 | J2: =Financials!K7 -> 2023 | ... L2: =Financials!M7 -> 2025 | O2: Chart Names
O3: Top Left | Q3: =Financials!B2 & " "& "("&Financials!B8& ") - Enterprise Value (EV)" -> Company name (Company symbol) - Enterprise Value (EV)
B4: Invested capital | C4: =Financials!D138 -> 0 | D4: =Financials!E138 -> 0 | E4: =Financials!F138 -> 0 | F4: =Financials!G138 -> 0 | G4: =Financials!H138 -> 0 | H4: =Financials!I138 -> 0 | I4: =Financials!J138 -> 0 | J4: =Financials!K138 -> 0 | ... L4: =Financials!M138 -> 0 | O4: Top Middle | Q4: =Financials!B2 & " "& "("&Financials!B8& ") - Earnings Power Value (EPV)" -> Company name (Company symbol) - Earnings Power Value (EPV)
B5: Present value of competitive advantage | C5: =Financials!D139 -> #DIV/0! | D5: =Financials!E139 -> #DIV/0! | E5: =Financials!F139 -> #DIV/0! | F5: =Financials!G139 -> #DIV/0! | G5: =Financials!H139 -> #DIV/0! | H5: =Financials!I139 -> #DIV/0! | I5: =Financials!J139 -> #DIV/0! | J5: =Financials!K139 -> #DIV/0! | ... L5: =Financials!M139 -> #DIV/0! | O5: Top Right | Q5: =Financials!B2 & " "& "("&Financials!B8& ") - Earnings Power Value (EPV) (Percentage of EV)" -> Company name (Company symbol) - Earnings Power Value (EPV) (Percentage of EV)
B6: Earnings Power Value | C6: =Financials!D140 -> #DIV/0! | D6: =Financials!E140 -> #DIV/0! | E6: =Financials!F140 -> #DIV/0! | F6: =Financials!G140 -> #DIV/0! | G6: =Financials!H140 -> #DIV/0! | H6: =Financials!I140 -> #DIV/0! | I6: =Financials!J140 -> #DIV/0! | J6: =Financials!K140 -> #DIV/0! | ... L6: =Financials!M140 -> #DIV/0! | O6: Mid Left: | Q6: =Financials!B2 & " "& "("&Financials!B8& ") - Market-Implied Value of NOPAT Growth" -> Company name (Company symbol) - Market-Implied Value of NOPAT Growth
B7: Market Implied value of NOPAT growth | C7: =Financials!D142 -> #DIV/0! | D7: =Financials!E142 -> #DIV/0! | E7: =Financials!F142 -> #DIV/0! | F7: =Financials!G142 -> #DIV/0! | G7: =Financials!H142 -> #DIV/0! | H7: =Financials!I142 -> #DIV/0! | I7: =Financials!J142 -> #DIV/0! | J7: =Financials!K142 -> #DIV/0! | ... L7: =Financials!M142 -> #DIV/0! | O7: Mid Right: | Q7: =Financials!B2 & " "& "("&Financials!B8& ") - Historical Valuation in US Thousands" -> Company name (Company symbol) - Historical Valuation in US Thousands
B8: Enterprise Value (EV) | C8: =Financials!D143 -> 0 | D8: =Financials!E143 -> 0 | E8: =Financials!F143 -> 0 | F8: =Financials!G143 -> 0 | G8: =Financials!H143 -> 0 | H8: =Financials!I143 -> 0 | I8: =Financials!J143 -> 0 | J8: =Financials!K143 -> 0 | ... L8: =Financials!M143 -> 0 | O8: Bottom Left | Q8: =Financials!B2 & " "& "("&Financials!B8& ") - Market-Implied Value of NOPAT Growth" -> Company name (Company symbol) - Market-Implied Value of NOPAT Growth
O9: Bottom Right | Q9: =Financials!B2 & " "& "("&Financials!B8& ") - Market-Implied Value of NOPAT Growth (Percentage of EV)" -> Company name (Company symbol) - Market-Implied Value of NOPAT Growth (Percentage of EV)
B10: Market Implied value of NOPAT growth | C10: =C7/C8 -> #DIV/0! | D10: =D7/D8 -> #DIV/0! | E10: =E7/E8 -> #DIV/0! | F10: =F7/F8 -> #DIV/0! | G10: =G7/G8 -> #DIV/0! | H10: =H7/H8 -> #DIV/0! | I10: =I7/I8 -> #DIV/0! | J10: =J7/J8 -> #DIV/0! | ... L10: =L7/L8 -> #DIV/0!
B11: Earnings Power Value | C11: =C6/C8 -> #DIV/0! | D11: =D6/D8 -> #DIV/0! | E11: =E6/E8 -> #DIV/0! | F11: =F6/F8 -> #DIV/0! | G11: =G6/G8 -> #DIV/0! | H11: =H6/H8 -> #DIV/0! | I11: =I6/I8 -> #DIV/0! | J11: =J6/J8 -> #DIV/0! | ... L11: =L6/L8 -> #DIV/0!
C13: =+C2 -> 2016 | D13: =+D2 -> 2017 | E13: =+E2 -> 2018 | F13: =+F2 -> 2019 | G13: =+G2 -> 2020 | H13: =+H2 -> 2021 | I13: =+I2 -> 2022 | J13: =+J2 -> 2023 | ... L13: =+L2 -> 2025
B14: Revenue | C14: =+Financials!D31 -> 0 | D14: =+Financials!E31 -> 0 | E14: =+Financials!F31 -> 0 | F14: =+Financials!G31 -> 0 | G14: =+Financials!H31 -> 0 | H14: =+Financials!I31 -> 0 | I14: =+Financials!J31 -> 0 | J14: =+Financials!K31 -> 0 | ... L14: =+Financials!M31 -> 0
B15: Operating Margin | C15: =+Financials!D39 -> #DIV/0! | D15: =+Financials!E39 -> #DIV/0! | E15: =+Financials!F39 -> #DIV/0! | F15: =+Financials!G39 -> #DIV/0! | G15: =+Financials!H39 -> #DIV/0! | H15: =+Financials!I39 -> #DIV/0! | I15: =+Financials!J39 -> #DIV/0! | J15: =+Financials!K39 -> #DIV/0! | ... L15: =+Financials!M39 -> #DIV/0!

Sheet Call-out
C2: =Financials!D116 -> 2016 | D2: =Financials!E116 -> 2017 | E2: =Financials!F116 -> 2018 | F2: =Financials!G116 -> 2019 | G2: =Financials!H116 -> 2020 | H2: =Financials!I116 -> 2021 | I2: =Financials!J116 -> 2022 | J2: =Financials!K116 -> 2023 | ... L2: =Financials!M116 -> 2025
B3: ROIC | C3: =Financials!D133 -> #DIV/0! | D3: =Financials!E133 -> #DIV/0! | E3: =Financials!F133 -> #DIV/0! | F3: =Financials!G133 -> #DIV/0! | G3: =Financials!H133 -> #DIV/0! | H3: =Financials!I133 -> #DIV/0! | I3: =Financials!J133 -> #DIV/0! | J3: =Financials!K133 -> #DIV/0! | ... L3: =Financials!M133 -> #DIV/0!
C5: =Financials!D116 -> 2016 | D5: =Financials!E116 -> 2017 | E5: =Financials!F116 -> 2018 | F5: =Financials!G116 -> 2019 | G5: =Financials!H116 -> 2020 | H5: =Financials!I116 -> 2021 | I5: =Financials!J116 -> 2022 | J5: =Financials!K116 -> 2023 | ... L5: =Financials!M116 -> 2025
B6: ROIC | C6: =C3 -> #DIV/0! | D6: =D3 -> #DIV/0! | E6: =E3 -> #DIV/0! | F6: =F3 -> #DIV/0! | G6: =G3 -> #DIV/0! | H6: =H3 -> #DIV/0! | I6: =I3 -> #DIV/0! | J6: =J3 -> #DIV/0! | ... L6: =L3 -> #DIV/0!
B7: Cost of Capital | C7: 0.1 | D7: =Financials!E134 -> 0.1 | E7: =Financials!F134 -> 0.1 | F7: =Financials!G134 -> 0.1 | G7: =Financials!H134 -> 0.1 | H7: =Financials!I134 -> 0.1 | I7: =Financials!J134 -> 0.1 | J7: =Financials!K134 -> 0.1 | K7: =Financials!L134 -> 0.1 | L7: 0.1
C9: =+C2 -> 2016 | D9: =+D2 -> 2017 | E9: =+E2 -> 2018 | F9: =+F2 -> 2019 | G9: =+G2 -> 2020 | H9: =+H2 -> 2021 | I9: =+I2 -> 2022 | J9: =+J2 -> 2023 | ... L9: =+L2 -> 2025
B10: % margin | C10: =+Financials!D124 -> #DIV/0! | D10: =+Financials!E124 -> #DIV/0! | E10: =+Financials!F124 -> #DIV/0! | F10: =+Financials!G124 -> #DIV/0! | G10: =+Financials!H124 -> #DIV/0! | H10: =+Financials!I124 -> #DIV/0! | I10: =+Financials!J124 -> #DIV/0! | J10: =+Financials!K124 -> #DIV/0! | ... L10: =+Financials!M124 -> #DIV/0!
B11: Scale | C11: =+Financials!D131 -> #DIV/0! | D11: =+Financials!E131 -> #DIV/0! | E11: =+Financials!F131 -> #DIV/0! | F11: =+Financials!G131 -> #DIV/0! | G11: =+Financials!H131 -> #DIV/0! | H11: =+Financials!I131 -> #DIV/0! | I11: =+Financials!J131 -> #DIV/0! | J11: =+Financials!K131 -> #DIV/0! | ... L11: =+Financials!M131 -> #DIV/0!
B12: ROIC | C12: =+C10*C11 -> #DIV/0! | D12: =+D10*D11 -> #DIV/0! | E12: =+E10*E11 -> #DIV/0! | F12: =+F10*F11 -> #DIV/0! | G12: =+G10*G11 -> #DIV/0! | H12: =+H10*H11 -> #DIV/0! | I12: =+I10*I11 -> #DIV/0! | J12: =+J10*J11 -> #DIV/0! | ... L12: =+L10*L11 -> #DIV/0!
C14: =C5 -> 2016 | D14: =D5 -> 2017 | E14: =E5 -> 2018 | F14: =F5 -> 2019 | G14: =G5 -> 2020 | H14: =H5 -> 2021 | I14: =I5 -> 2022 | J14: 2022 | K14: 2023 | L14: =+L2 -> 2025
B15: SHAK - scale | C15: =Financials!D131 -> #DIV/0! | D15: =Financials!E131 -> #DIV/0! | E15: =Financials!F131 -> #DIV/0! | F15: =Financials!G131 -> #DIV/0! | G15: =Financials!H131 -> #DIV/0! | H15: =Financials!I131 -> #DIV/0! | I15: =Financials!J131 -> #DIV/0! | J15: =Financials!K131 -> #DIV/0! | ... L15: =Financials!M131 -> #DIV/0!
B16: CMG - scale | C16: 2.5692396 | D16: 2.5285299 | E16: 2.7227111 | F16: 2.7894053 | G16: 1.2784167 | H16: 1.2091398 | I16: 1.3987815 | J16: 1.5677971 | K16: 1.56
B17: MCD - scale
B19: SHAK - operating margin
B20: CMG operating margin
B21: MCD - operating margin | C21: 0.28941487 | D21: 0.31758661 | E21: 0.36763159 | F21: 0.40607962 | G21: 0.4189212 | H21: 0.38130343 | I21: 0.44593914
