Workbook

Sheet Ledger
A1: key | B1: period | C1: value | D1: unit | E1: source_url
A2: revenue | B2: FY2022 | C2: 6622 | D2: USD millions | E2: https://www.globenewswire.com/news-release/2024/03/06/2841834/0/en/Constellation-Software-Inc-Announces-Results-for-the-Fourth-Quarter-and-Year-Ended-December-31-2023-and-Declares-Quarterly-Dividend.html
A3: revenue | B3: FY2023 | C3: 8407 | D3: USD millions | E3: https://www.globenewswire.com/news-release/2024/03/06/2841834/0/en/Constellation-Software-Inc-Announces-Results-for-the-Fourth-Quarter-and-Year-Ended-December-31-2023-and-Declares-Quarterly-Dividend.html
A4: revenue | B4: FY2024 | C4: 10066 | D4: USD millions | E4: https://www.csisoftware.com/constellation-software-inc-announces-results-for-the-fourth-quarter-and-year-ended-december-31-2024-and-declares-quarterly-dividend/
A5: revenue | B5: FY2025 | C5: 11623 | D5: USD millions | E5: https://www.globenewswire.com/news-release/2026/03/09/3251696/0/en/constellation-software-inc-announces-results-for-the-fourth-quarter-and-year-ended-december-31-2025-and-declares-quarterly-dividend.html
A6: revenue | B6: Q1 2025 | C6: 2650 | D6: USD millions | E6: https://finance.yahoo.com/news/constellation-software-first-quarter-2025-135734558.html
A7: revenue | B7: Q1 2026 | C7: 3181 | D7: USD millions | E7: https://www.csisoftware.com/constellation-software-inc-announces-results-for-the-first-quarter-ended-march-31-2026-and-declares-quarterly-dividend/
A8: revenue | B8: Q2 2025 | C8: 2844 | D8: USD millions | E8: https://www.globenewswire.com/news-release/2026/08/11/3343207/0/en/constellation-software-inc-announces-results-for-the-second-quarter-ended-june-30-2026-and-declares-quarterly-dividend.html
A9: revenue | B9: Q2 2026 | C9: 3335 | D9: USD millions | E9: https://www.globenewswire.com/news-release/2026/08/11/3343207/0/en/constellation-software-inc-announces-results-for-the-second-quarter-ended-june-30-2026-and-declares-quarterly-dividend.html
A10: revenue | B10: H1 2025 | C10: 5498 | D10: USD millions | E10: https://www.csisoftware.com/constellation-software-inc-announces-results-for-the-second-quarter-ended-june-30-2026-and-declares-quarterly-dividend/
A11: revenue | B11: H1 2026 | C11: 6516 | D11: USD millions | E11: https://www.csisoftware.com/constellation-software-inc-announces-results-for-the-second-quarter-ended-june-30-2026-and-declares-quarterly-dividend/
A12: maintenance_recurring_revenue | B12: FY2023 | C12: 5985 | D12: USD millions | E12: https://www.csisoftware.com/docs/default-source/investor-relations/statutory-filings/q4-2023-shareholder-report.pdf?sfvrsn=91ffcfe7_3
A13: maintenance_recurring_revenue | B13: FY2024 | C13: 7396 | D13: USD millions | E13: https://www.csisoftware.com/docs/default-source/press-releases/csi---press-release-q4-2024---final.pdf?sfvrsn=a6da3ec_3/+CSI---Press-Release-Q4-2024---Final+.pdf
... A101: enterprise_value_usd | B101: 2026-05 | C101: 46000 | D101: CAD millions | E101: https://multiples.vc/public-comps/constellation-software-valuation-multiples
A102: price_date | B102: current | C102: 2026-09-11 | D102: date | E102: https://www.stockopedia.com/share-prices/constellation-software-TSE:CSU/
A103: market_cap_cad | B103: 2026-09-08 | C103: 65183 | D103: CAD millions | E103: https://stockanalysis.com/quote/tsx/CSU/market-cap/
A104: usdcad | B104: 2026-09 | C104: 1.3594 | D104: CAD per USD | E104: https://stockanalysis.com/quote/tsx/CSU/market-cap/ and https://tradingeconomics.com/csu:cn:market-capitalization

Sheet Metrics
A1: metric | B1: period | C1: value | D1: formula | E1: inputs_used | F1: note
A2: revenue_growth_yoy | B2: FY2023 | C2: =Ledger!$C$3/Ledger!$C$2-1 | D2: revenue[FY2023]/revenue[FY2022] - 1 | E2: revenue.FY2023, revenue.FY2022
A3: revenue_growth_yoy | B3: FY2024 | C3: =Ledger!$C$4/Ledger!$C$3-1 | D3: revenue[FY2024]/revenue[FY2023] - 1 | E3: revenue.FY2024, revenue.FY2023
A4: revenue_growth_yoy | B4: FY2025 | C4: =Ledger!$C$5/Ledger!$C$4-1 | D4: revenue[FY2025]/revenue[FY2024] - 1 | E4: revenue.FY2025, revenue.FY2024
A5: revenue_growth_yoy | B5: Q1 2026 | C5: =Ledger!$C$7/Ledger!$C$6-1 | D5: revenue[Q1 2026]/revenue[Q1 2025] - 1 | E5: revenue.Q1 2026, revenue.Q1 2025
A6: revenue_growth_yoy | B6: Q2 2026 | C6: =Ledger!$C$9/Ledger!$C$8-1 | D6: revenue[Q2 2026]/revenue[Q2 2025] - 1 | E6: revenue.Q2 2026, revenue.Q2 2025
A7: revenue_growth_yoy | B7: H1 2026 | C7: =Ledger!$C$11/Ledger!$C$10-1 | D7: revenue[H1 2026]/revenue[H1 2025] - 1 | E7: revenue.H1 2026, revenue.H1 2025
A8: revenue_growth_yoy | B8: FY2022 | D8: revenue[FY2022]/revenue[FY2021] - 1 | F8: no FY2021 revenue in ledger
A9: maintenance_share_of_revenue | B9: FY2022 | D9: maintenance_recurring_revenue[FY2022]/revenue[FY2022] | F9: maintenance_recurring_revenue or revenue missing for this period
A10: maintenance_share_of_revenue | B10: FY2023 | C10: =Ledger!$C$12/Ledger!$C$3 | D10: maintenance_recurring_revenue[FY2023]/revenue[FY2023] | E10: maintenance_recurring_revenue.FY2023, revenue.FY2023
A11: maintenance_share_of_revenue | B11: FY2024 | C11: =Ledger!$C$13/Ledger!$C$4 | D11: maintenance_recurring_revenue[FY2024]/revenue[FY2024] | E11: maintenance_recurring_revenue.FY2024, revenue.FY2024
A12: maintenance_share_of_revenue | B12: FY2025 | D12: maintenance_recurring_revenue[FY2025]/revenue[FY2025] | F12: maintenance_recurring_revenue or revenue missing for this period
A13: maintenance_share_of_revenue | B13: Q1 2025 | C13: =Ledger!$C$14/Ledger!$C$6 | D13: maintenance_recurring_revenue[Q1 2025]/revenue[Q1 2025] | E13: maintenance_recurring_revenue.Q1 2025, revenue.Q1 2025
A14: maintenance_share_of_revenue | B14: Q1 2026 | C14: =Ledger!$C$15/Ledger!$C$7 | D14: maintenance_recurring_revenue[Q1 2026]/revenue[Q1 2026] | E14: maintenance_recurring_revenue.Q1 2026, revenue.Q1 2026
A15: maintenance_share_of_revenue | B15: Q2 2025 | D15: maintenance_recurring_revenue[Q2 2025]/revenue[Q2 2025] | F15: maintenance_recurring_revenue or revenue missing for this period
A16: maintenance_share_of_revenue | B16: Q2 2026 | C16: =Ledger!$C$16/Ledger!$C$9 | D16: maintenance_recurring_revenue[Q2 2026]/revenue[Q2 2026] | E16: maintenance_recurring_revenue.Q2 2026, revenue.Q2 2026
A17: maintenance_share_of_revenue | B17: H1 2025 | D17: maintenance_recurring_revenue[H1 2025]/revenue[H1 2025] | F17: maintenance_recurring_revenue or revenue missing for this period
A18: maintenance_share_of_revenue | B18: H1 2026 | C18: =Ledger!$C$17/Ledger!$C$11 | D18: maintenance_recurring_revenue[H1 2026]/revenue[H1 2026] | E18: maintenance_recurring_revenue.H1 2026, revenue.H1 2026
A19: maintenance_share_of_revenue | B19: LTM to Q2 2026 | D19: maintenance_recurring_revenue[LTM to Q2 2026]/revenue[LTM to Q2 2026] | F19: maintenance_recurring_revenue or revenue missing for this period
A20: maintenance_growth_yoy | B20: FY2023 | D20: maintenance_recurring_revenue[FY2023]/maintenance_recurring_revenue[FY2022] - 1 | F20: maintenance_recurring_revenue missing for current or prior period
A21: maintenance_growth_yoy | B21: FY2024 | C21: 0.23575606 | D21: maintenance_recurring_revenue[FY2024]/maintenance_recurring_revenue[FY2023] - 1 | E21: maintenance_recurring_revenue.FY2024, maintenance_recurring_revenue.FY2023
A22: maintenance_growth_yoy | B22: FY2025 | D22: maintenance_recurring_revenue[FY2025]/maintenance_recurring_revenue[FY2024] - 1 | F22: maintenance_recurring_revenue missing for current or prior period
A23: maintenance_growth_yoy | B23: Q1 2026 | C23: 0.22244489 | D23: maintenance_recurring_revenue[Q1 2026]/maintenance_recurring_revenue[Q1 2025] - 1 | E23: maintenance_recurring_revenue.Q1 2026, maintenance_recurring_revenue.Q1 2025
A24: maintenance_growth_yoy | B24: Q2 2026 | D24: maintenance_recurring_revenue[Q2 2026]/maintenance_recurring_revenue[Q2 2025] - 1 | F24: maintenance_recurring_revenue missing for current or prior period
A25: maintenance_growth_yoy | B25: H1 2026 | D25: maintenance_recurring_revenue[H1 2026]/maintenance_recurring_revenue[H1 2025] - 1 | F25: maintenance_recurring_revenue missing for current or prior period
A26: net_margin | B26: FY2022 | C26: =Ledger!$C$33/Ledger!$C$2 | D26: net_income_attributable[FY2022]/revenue[FY2022] | E26: net_income_attributable.FY2022, revenue.FY2022
A27: net_margin | B27: FY2023 | C27: =Ledger!$C$34/Ledger!$C$3 | D27: net_income_attributable[FY2023]/revenue[FY2023] | E27: net_income_attributable.FY2023, revenue.FY2023
A28: net_margin | B28: FY2024 | C28: =Ledger!$C$35/Ledger!$C$4 | D28: net_income_attributable[FY2024]/revenue[FY2024] | E28: net_income_attributable.FY2024, revenue.FY2024
A29: net_margin | B29: FY2025 | C29: =Ledger!$C$36/Ledger!$C$5 | D29: net_income_attributable[FY2025]/revenue[FY2025] | E29: net_income_attributable.FY2025, revenue.FY2025
A30: net_margin | B30: Q1 2025 | C30: =Ledger!$C$37/Ledger!$C$6 | D30: net_income_attributable[Q1 2025]/revenue[Q1 2025] | E30: net_income_attributable.Q1 2025, revenue.Q1 2025
A31: net_margin | B31: Q1 2026 | C31: =Ledger!$C$38/Ledger!$C$7 | D31: net_income_attributable[Q1 2026]/revenue[Q1 2026] | E31: net_income_attributable.Q1 2026, revenue.Q1 2026
A32: net_margin | B32: Q2 2025 | C32: =Ledger!$C$39/Ledger!$C$8 | D32: net_income_attributable[Q2 2025]/revenue[Q2 2025] | E32: net_income_attributable.Q2 2025, revenue.Q2 2025
A33: net_margin | B33: Q2 2026 | C33: =Ledger!$C$40/Ledger!$C$9 | D33: net_income_attributable[Q2 2026]/revenue[Q2 2026] | E33: net_income_attributable.Q2 2026, revenue.Q2 2026
A34: net_margin | B34: H1 2025 | C34: =Ledger!$C$41/Ledger!$C$10 | D34: net_income_attributable[H1 2025]/revenue[H1 2025] | E34: net_income_attributable.H1 2025, revenue.H1 2025
A35: net_margin | B35: H1 2026 | C35: =Ledger!$C$42/Ledger!$C$11 | D35: net_income_attributable[H1 2026]/revenue[H1 2026] | E35: net_income_attributable.H1 2026, revenue.H1 2026
A36: net_margin | B36: LTM to Q2 2026 | D36: net_income_attributable[LTM to Q2 2026]/revenue[LTM to Q2 2026] | F36: net_income_attributable or revenue missing
A37: adjusted_ebita_margin | B37: FY2022 | D37: adjusted_ebita[FY2022]/revenue[FY2022] | F37: adjusted_ebita not found in ledger for any period (see ledger unmapped[] gap note)
A38: adjusted_ebita_margin | B38: FY2023 | D38: adjusted_ebita[FY2023]/revenue[FY2023] | F38: adjusted_ebita not found in ledger for any period (see ledger unmapped[] gap note)
A39: adjusted_ebita_margin | B39: FY2024 | D39: adjusted_ebita[FY2024]/revenue[FY2024] | F39: adjusted_ebita not found in ledger for any period (see ledger unmapped[] gap note)
A40: adjusted_ebita_margin | B40: FY2025 | D40: adjusted_ebita[FY2025]/revenue[FY2025] | F40: adjusted_ebita not found in ledger for any period (see ledger unmapped[] gap note)
...

Sheet Valuation
A1: item | B1: value | C1: formula | D1: note
A2: market_cap_usd | B2: 47950 | C2: market_cap_usd[2026-09] taken directly from ledger | D2: usdcad is not present anywhere in ledger, so no independent CAD->USD conversion of share_price_cad*shares_outstanding was possible; the ledger's own USD market cap figure is used as-is. Ledger flags a conflicting CAD 65,183mm figure from another source, not cross-checked here.
A3: implied_share_price_usd | B3: 2262.8598 | C3: market_cap_usd[2026-09] / shares_outstanding[Q2 2026] | D3: Derived because no share_price_usd or usdcad exists in ledger to convert share_price_cad directly.
A4: pe_trailing | B4: 93.652344 | C4: market_cap_usd[2026-09] / net_income_attributable[FY2025] | D4: Uses FY2025 net income (most recent full fiscal year) as trailing NI; no LTM net income figure exists in ledger.
A5: price_to_fcfa2s_per_share | B5: 23.62069 | C5: implied_share_price_usd / (fcfa2s[LTM to Q2 2026]/shares_outstanding[Q2 2026])
A6: ev_to_adjusted_ebita | C6: enterprise_value_usd / adjusted_ebita | D6: adjusted_ebita not present anywhere in ledger
A7: ev_to_revenue | C7: enterprise_value_usd / revenue[FY2025] | D7: enterprise_value_usd ledger entry (46000, period 2026-05) is explicitly noted as CAD-denominated despite the key name, and usdcad is not present in ledger, so it cannot be reliably converted to match USD-denominated revenue; left null rather than mixing currencies.
A8: fcfa2s_yield | B8: 0.042335766 | C8: (fcfa2s[LTM to Q2 2026]/shares_outstanding[Q2 2026]) / implied_share_price_usd
A9: dividend_yield | B9: 0.0017676747 | C9: dividends_per_share[FY2025] / implied_share_price_usd | D9: Uses FY2025 annual dividend per share as trailing-12m proxy (quarterly Q1/Q2 2026 figures of 1.0 each annualize to the same 4.0 run-rate).
A10: price_date | B10: 2026-09-11 | C10: price_date[current] from ledger

Sheet Peers
A1: peer | B1: metric | C1: value | D1: unit/formula | E1: source_url
A2: Topicus.com (TOI) | B2: H1 2026 revenue | C2: 872.9 | D2: EUR millions | E2: https://www.globenewswire.com/news-release/2026/08/05/3339823/0/en/constellation-software-inc-and-topicus-com-inc-announce-results-for-topicus-com-inc-for-the-second-quarter-ended-june-30-2026.html
A3: Topicus.com (TOI) | B3: H1 2026 revenue growth yoy | C3: 20 | D3: percent | E3: https://www.globenewswire.com/news-release/2026/08/05/3339823/0/en/constellation-software-inc-and-topicus-com-inc-announce-results-for-topicus-com-inc-for-the-second-quarter-ended-june-30-2026.html
A4: Topicus.com (TOI) | B4: H1 2026 organic growth | C4: 5 | D4: percent | E4: https://www.globenewswire.com/news-release/2026/08/05/3339823/0/en/constellation-software-inc-and-topicus-com-inc-announce-results-for-topicus-com-inc-for-the-second-quarter-ended-june-30-2026.html
A5: Topicus.com (TOI) | B5: Q2 2026 revenue | C5: 437.3 | D5: EUR millions | E5: https://www.globenewswire.com/news-release/2026/08/05/3339823/0/en/constellation-software-inc-and-topicus-com-inc-announce-results-for-topicus-com-inc-for-the-second-quarter-ended-june-30-2026.html
A6: Topicus.com (TOI) | B6: Q1 2026 revenue | C6: 435.7 | D6: EUR millions | E6: https://www.globenewswire.com/news-release/2026/08/05/3339823/0/en/constellation-software-inc-and-topicus-com-inc-announce-results-for-topicus-com-inc-for-the-second-quarter-ended-june-30-2026.html
A7: Topicus.com (TOI) | B7: share_price | C7: 100.5 | D7: CAD | E7: https://www.investing.com/equities/topicus.com
A8: Topicus.com (TOI) | B8: market_cap | C8: 8390 | D8: CAD millions | E8: https://www.gurufocus.com/term/mktcap/TSXV:TOI
A9: Lumine Group (LMN) | B9: H1 2026 revenue | C9: 443.4 | D9: USD millions | E9: https://www.globenewswire.com/news-release/2026/08/04/3338792/0/en/Lumine-Group-Inc-Announces-Results-for-the-Second-Quarter-Ended-June-30-2026.html
A10: Lumine Group (LMN) | B10: H1 2026 revenue growth yoy | C10: 22 | D10: percent | E10: https://www.globenewswire.com/news-release/2026/08/04/3338792/0/en/Lumine-Group-Inc-Announces-Results-for-the-Second-Quarter-Ended-June-30-2026.html
A11: Lumine Group (LMN) | B11: Q1 2026 revenue | C11: 208.3 | D11: USD millions | E11: https://finance.yahoo.com/markets/stocks/articles/lumine-group-inc-announces-results-200100205.html
A12: Lumine Group (LMN) | B12: Q1 2026 organic growth | C12: 0 | D12: percent | E12: https://finance.yahoo.com/markets/stocks/articles/lumine-group-inc-announces-results-200100205.html
A13: Lumine Group (LMN) | B13: Q1 2026 organic growth fx-adj | C13: -2 | D13: percent | E13: https://finance.yahoo.com/markets/stocks/articles/lumine-group-inc-announces-results-200100205.html
... A20: Descartes Systems (DSG) | B20: FY2026 cash | C20: 356.5 | D20: USD millions | E20: https://www.theglobeandmail.com/investing/markets/stocks/DSGX-Q/pressreleases/726305/descartes-systems-group-posts-record-fiscal-2026-revenue-and-earnings-amid-logistics-turbulence/
A21: Descartes Systems (DSG) | B21: FY2026 net_margin | C21: 0.22469136 | D21: FY2026 net income/FY2026 revenue
A22: Descartes Systems (DSG) | B22: FY2026 adjusted_ebitda_margin | C22: 0.45198903 | D22: FY2026 adjusted ebitda/FY2026 revenue
A23: Enghouse Systems (ENGH) | B23: H1 2026 revenue | C23: 234.4 | D23: USD millions | E23: https://finance.yahoo.com/markets/stocks/articles/enghouse-systems-ltd-eghsf-q2-010050704.html
A24: Enghouse Systems (ENGH) | B24: H1 2026 revenue growth yoy | C24: -5.8 | D24: percent | E24: https://finance.yahoo.com/markets/stocks/articles/enghouse-systems-ltd-eghsf-q2-010050704.html
A25: Enghouse Systems (ENGH) | B25: Q2 2026 revenue | C25: 114.3 | D25: USD millions | E25: https://finance.yahoo.com/markets/stocks/articles/enghouse-systems-ltd-eghsf-q2-010050704.html
A26: Enghouse Systems (ENGH) | B26: Q2 2026 net income | C26: 16.3 | D26: USD millions | E26: https://finance.yahoo.com/markets/stocks/articles/enghouse-systems-ltd-eghsf-q2-010050704.html
A27: Enghouse Systems (ENGH) | B27: Q2 2026 adjusted ebitda | C27: 26.5 | D27: USD millions | E27: https://finance.yahoo.com/markets/stocks/articles/enghouse-systems-ltd-eghsf-q2-010050704.html
A28: Enghouse Systems (ENGH) | B28: cash | C28: 269.7 | D28: USD millions | E28: https://finance.yahoo.com/markets/stocks/articles/enghouse-systems-ltd-eghsf-q2-010050704.html
A29: Enghouse Systems (ENGH) | B29: Q2 2026 net_margin | C29: 0.14260717 | D29: Q2 2026 net income/Q2 2026 revenue
A30: Enghouse Systems (ENGH) | B30: Q2 2026 adjusted_ebitda_margin | C30: 0.23184602 | D30: Q2 2026 adjusted ebitda/Q2 2026 revenue
A31: Roper Technologies (ROP) | B31: status | C31: no data retrieved, WebSearch budget exhausted per stage1 peers_large.json
A32: Tyler Technologies (TYL) | B32: status | C32: no data retrieved, WebSearch budget exhausted per stage1 peers_large.json
A33: Open Text (OTEX) | B33: status | C33: no data retrieved, WebSearch budget exhausted per stage1 peers_large.json
A34: Constellation Software (CSU) [same definitions] | B34: H1 2026 revenue_growth_yoy | C34: 0.18515824
A35: Constellation Software (CSU) [same definitions] | B35: H1 2026 organic_growth_pct | C35: 4
A36: Constellation Software (CSU) [same definitions] | B36: H1 2026 net_margin | C36: 0.098373235
A37: Constellation Software (CSU) [same definitions] | B37: Q1 2026 revenue_growth_yoy | C37: 0.20037736
A38: Constellation Software (CSU) [same definitions] | B38: Q1 2026 organic_growth_pct | C38: 6
A39: Constellation Software (CSU) [same definitions] | B39: Q1 2026 net_margin | C39: 0.11537252
A40: Constellation Software (CSU) [same definitions] | B40: Q2 2026 revenue_growth_yoy | C40: 0.17264416
A41: Constellation Software (CSU) [same definitions] | B41: Q2 2026 organic_growth_pct | C41: 3
A42: Constellation Software (CSU) [same definitions] | B42: Q2 2026 net_margin | C42: 0.082158921
A43: Constellation Software (CSU) [same definitions] | B43: adjusted_ebitda_margin
A44: Constellation Software (CSU) [same definitions] | B44: note | C44: CSU has no adjusted_ebita/EBITDA figure in ledger, so ebitda margin is null for all periods.

Sheet ScenarioGrid
A1: Scenario inputs
A2: current_fcfa2s_per_share | B2: 95.799906
A3: current_multiple | B3: 23.62069
A4: entry_price_usd | B4: 2262.8598
A6: 5yr IRR grid (rows=fcfa2s growth, cols=exit multiple x fcfa2s)
A7: growth \ exit_mult | B7: 15x | C7: 20x | D7: 25x | E7: 30x | F7: 35x
A8: 0 | B8: =(($B$2*(1+$A8)^5)*15/$B$4)^(1/5)-1 | C8: =(($B$2*(1+$A8)^5)*20/$B$4)^(1/5)-1 | D8: =(($B$2*(1+$A8)^5)*25/$B$4)^(1/5)-1 | E8: =(($B$2*(1+$A8)^5)*30/$B$4)^(1/5)-1 | F8: =(($B$2*(1+$A8)^5)*35/$B$4)^(1/5)-1
A9: 0.05 | B9: =(($B$2*(1+$A9)^5)*15/$B$4)^(1/5)-1 | C9: =(($B$2*(1+$A9)^5)*20/$B$4)^(1/5)-1 | D9: =(($B$2*(1+$A9)^5)*25/$B$4)^(1/5)-1 | E9: =(($B$2*(1+$A9)^5)*30/$B$4)^(1/5)-1 | F9: =(($B$2*(1+$A9)^5)*35/$B$4)^(1/5)-1
A10: 0.1 | B10: =(($B$2*(1+$A10)^5)*15/$B$4)^(1/5)-1 | C10: =(($B$2*(1+$A10)^5)*20/$B$4)^(1/5)-1 | D10: =(($B$2*(1+$A10)^5)*25/$B$4)^(1/5)-1 | E10: =(($B$2*(1+$A10)^5)*30/$B$4)^(1/5)-1 | F10: =(($B$2*(1+$A10)^5)*35/$B$4)^(1/5)-1
A11: 0.15 | B11: =(($B$2*(1+$A11)^5)*15/$B$4)^(1/5)-1 | C11: =(($B$2*(1+$A11)^5)*20/$B$4)^(1/5)-1 | D11: =(($B$2*(1+$A11)^5)*25/$B$4)^(1/5)-1 | E11: =(($B$2*(1+$A11)^5)*30/$B$4)^(1/5)-1 | F11: =(($B$2*(1+$A11)^5)*35/$B$4)^(1/5)-1
A12: 0.2 | B12: =(($B$2*(1+$A12)^5)*15/$B$4)^(1/5)-1 | C12: =(($B$2*(1+$A12)^5)*20/$B$4)^(1/5)-1 | D12: =(($B$2*(1+$A12)^5)*25/$B$4)^(1/5)-1 | E12: =(($B$2*(1+$A12)^5)*30/$B$4)^(1/5)-1 | F12: =(($B$2*(1+$A12)^5)*35/$B$4)^(1/5)-1

Sheet PostReview
A1: item | B1: value | C1: formula | D1: note
A2: usdcad_derived | B2: 1.3594 | C2: market_cap_cad[2026-09-08] / market_cap_usd[2026-09] | D2: Two third party market caps on different days; low confidence, see sensitivity below.
A3: implied_usdcad_in_report_entry | B3: 1.2497195 | C3: share_price_cad[2026-09-11] / implied_share_price_usd
A4: net_income_ltm | B4: 961 | C4: net_income_attributable[FY2025] - [H1 2025] + [H1 2026]
A5: pe_trailing_ltm | B5: 49.895942 | C5: market_cap_usd[2026-09] / net_income_ltm | D5: Replaces the FY2025 only P/E as the trailing figure. Still distorted by the Q2 2026 FX and IRGA gains.
A6: pe_trailing_ltm_at_derived_fx | B6: 45.870185 | C6: (share_price_cad / usdcad * shares_outstanding[Q2 2026]) / net_income_ltm
A7: net_debt_rollforward | B7: 1388.19 | C7: net_debt[Q1 2026] + acquisitions_cash_spent[Q2 2026] - fcfa2s[Q2 2026] + dividends_per_share[Q2 2026]*shares_outstanding[Q2 2026] | D7: Estimate of Q2 2026 net debt if the reported 5,000 / 2,800 balance sheet is a stale September 2025 snapshot. Ignores FX, deferred consideration and working capital.
A8: net_debt_rollforward_to_ltm_fcfa2s | B8: 0.68383744 | C8: net_debt_rollforward / fcfa2s[LTM to Q2 2026]
A9: acquisitions_h1_2026_cash_vs_fy2025 | B9: 0.90500317 | C9: acquisitions_cash_spent[H1 2026] / acquisitions_cash_spent[FY2025]
A10: acquisitions_h1_2026_total_consideration | B10: 1702 | C10: Q1 2026 total consideration 809 + Q2 2026 total consideration 893 (from stage1 q1_2026.json and q2_2026.json)
A12: FX sensitivity | B12: usdcad | C12: entry_price_usd | D12: multiple_price_to_fcfa2s | E12: fcfa2s_yield | F12: irr_bear | G12: irr_base | H12: irr_bull | I12: irr_expected | J12: buy_price_usd_for_12pct | K12: buy_price_cad_for_12pct | L12: price_usd_where_irr_falls_below_8pct | M12: price_cad_where_irr_falls_below_8pct | N12: derived_rate
B13: 1.25 | C13: 2262.352 | D13: 23.615389 | E13: 0.04234527 | F13: -0.04111057 | G13: 0.11260669 | H13: 0.20637706 | I13: 0.085245588 | J13: 1932.4586 | K13: 2415.5733 | L13: 2317.8298 | M13: 2897.2873 | N13: FALSE
B14: 1.3 | C14: 2175.3385 | D14: 22.707104 | E14: 0.04403908 | F14: -0.033559326 | G14: 0.12136846 | H14: 0.21587727 | I14: 0.093791884 | J14: 1932.4586 | K14: 2512.1962 | L14: 2317.8298 | M14: 3013.1788 | N14: FALSE
B15: 1.35 | C15: 2094.7704 | D15: 21.866101 | E15: 0.045732891 | F15: -0.026236969 | G15: 0.12986464 | H15: 0.22508952 | I15: 0.10207913 | J15: 1932.4586 | K15: 2608.8192 | L15: 2317.8298 | M15: 3129.0702 | N15: FALSE
B16: 1.3594 | C16: 2080.2854 | D16: 21.714901 | E16: 0.046051328 | F16: -0.024884675 | G16: 0.13143372 | H16: 0.22679083 | I16: 0.10360962 | J16: 1932.4586 | K16: 2626.9843 | L16: 2317.8298 | M16: 3150.8578 | N16: TRUE
B17: 1.4 | C17: 2019.9571 | D17: 21.085168 | E17: 0.047426702 | F17: -0.019128455 | G17: 0.13811271 | H17: 0.23403272 | I17: 0.11012436 | J17: 1932.4586 | K17: 2705.4421 | L17: 2317.8298 | M17: 3244.9617 | N17: FALSE
